Workbook

Sheet Petunjuk
A1: Template Pencatatan Hasil Pengujian — ECPresent
A2: Riset: Optimasi Latensi dan Peningkatan Ketahanan Sistem Feedback Presentasi Asinkron Berbasis Gemini API
B5: 1. Legenda warna
B6: Kuning | C6: Diisi oleh penguji (atau ditempel dari CSV hasil export).
B7: Abu-abu | C7: Rumus otomatis. Jangan diketik manual.
B8: Biru tua | C8: Judul kolom.
B9: Hijau | C9: Contoh format pengisian (hanya di sheet ini, tidak ikut dihitung).
B11: 2. Cara mengisi
B12: a. Jalankan pengujian (lihat experiment/README.md). Setiap fase memakai label berbeda, mis. baseline, optimized, baseline-fault30.
B13: b. Jalankan npm run experiment:export di folder backend. Script membuat file experiment/results/template_video_<waktu>.csv yang urutan kolomnya sama persis dengan sheet 'Data Pengujian' (kolom A–S).
B14: c. Buka CSV itu, salin baris data (tanpa judul kolom), lalu tempel ke sheet 'Data Pengujian' mulai sel A6. Baris contoh yang sudah terisi (label, mode, kode sampel) boleh tertimpa.
B15: d. Jika Excel memakai format Indonesia (koma sebagai desimal), jalankan export dengan npm run experiment:export -- --decimal-comma supaya angka terbaca benar.
B16: e. Bisa juga diisi manual dari console backend (baris [TIMING]) atau dari tabel processing_logs. Gunakan tabel pemetaan di bawah.
B17: f. Sheet 'Ringkasan Latensi', 'Ringkasan Ketahanan', 'Uji Berpasangan', dan 'Grafik' terisi otomatis. Ganti Label A/B di 'Ringkasan Latensi' atau 'Uji Berpasangan' untuk membandingkan fase lain.
B18: g. Data tahap jawaban QnA (Fase D, opsional) diisi di sheet 'Data QnA' dari template_answer_<waktu>.csv (npm run experiment:export -- --kind ANSWER).
B20: 3. Pemetaan kolom (sheet ← kolom CSV processing_logs_video_*.csv)
B21: Kolom sheet | C21: Kolom CSV / database | D21: Keterangan
B22: Label Fase | C22: experiment_label | D22: Label fase pengujian (EXPERIMENT_LABEL atau --label runner).
B23: Mode | C23: pipeline_mode | D23: baseline / optimized.
B24: Kode Sampel | C24: sample_label | D24: Nama file video tanpa ekstensi, atau judul presentasi di aplikasi.
B25: Durasi Target (mnt) | C25: duration_bucket_min | D25: Kelompok durasi terdekat: 1, 3, 5, 8.
B26: Durasi Aktual (dtk) | C26: video_duration_sec | D26: Dibaca dari header MP4/MOV.
B27: Ukuran File (MB) | C27: file_size_mb
B28: Terima File di Server (dtk) | C28: server_receive_s | D28: Lama server menerima file dari HP/runner.
B29: Upload ke Gemini (dtk) | C29: gemini_upload_s | D29: Total semua percobaan upload.
B30: Tunggu File ACTIVE (dtk) | C30: file_active_s | D30: Polling sampai file siap diproses Gemini.
B31: generateContent (dtk) | C31: generate_s | D31: Total semua percobaan generateContent.
B32: Simpan ke DB (dtk) | C32: save_s
B33: Total Server (dtk) | C33: total_s | D33: Request diterima → feedback tersimpan. Variabel terikat utama.
B34: Total Dirasakan User (dtk) | C34: client_total_s | D34: Tekan Upload → hasil tampil di aplikasi/runner.
B35: Jumlah Percobaan generate | C35: generate_attempts | D35: > 1 berarti terjadi retry.
B36: Status Akhir | C36: outcome | D36: Lihat definisi di bawah.
B37: Tahap Gagal | C37: failure_stage | D37: Tahap tempat error terjadi.
B38: Catatan | C38: error_message | D38: Pesan error, kondisi jaringan, dsb.
B40: 4. Definisi Status Akhir
B41: Status | C41: Kondisi | D41: Arti
B42: SUCCESS | C42: status = SUCCESS | D42: Analisis Gemini berhasil.
B43: SILENT_FAILURE | C43: status = FALLBACK | D43: Gemini gagal tetapi user tetap menerima feedback mock skor 0 tanpa diberi tahu (khas baseline).
B44: FAILED | C44: status = FAILED | D44: Gagal dan user diberi tahu lewat dialog di aplikasi (khas optimized).
B45: TIMEOUT | C45: status = TIMEOUT | D45: Dihentikan karena melewati batas waktu (watchdog/deadline).
...

Sheet Data Pengujian
A1: Data Pengujian — Tahap Analisis Video
A2: Satu baris = satu video yang diuji. Isi kolom kuning (atau tempel dari template_video_*.csv mulai sel A6). Kolom abu-abu dihitung otomatis.
A4: Identitas Sampel | I4: Waktu per Tahap (detik) | P4: Hasil | T4: Dihitung Otomatis
A5: No | B5: Tanggal | C5: Label Fase | D5: Mode | E5: Kode Sampel | F5: Durasi Target (mnt) | G5: Durasi Aktual (dtk) | H5: Ukuran File (MB) | I5: Terima File di Server (dtk) | J5: Upload ke Gemini (dtk) | K5: Tunggu File ACTIVE (dtk) | L5: generateContent (dtk) | M5: Simpan ke DB (dtk) | N5: Total Server (dtk) | O5: Total Dirasakan User (dtk) | P5: Jumlah Percobaan generate | Q5: Status Akhir | R5: Tahap Gagal | S5: Catatan | T5: Sukses (1/0) | U5: Lain-lain: antre + jeda retry (dtk) | V5: Porsi generateContent dari Total | W5: Latensi per Menit Video (dtk/mnt)
A6: 1 | C6: baseline | D6: baseline | E6: 01min_01 | F6: 1 | T6: =IF(Q6="","",IF(Q6="SUCCESS",1,0)) | U6: =IF(OR(N6="",Q6<>"SUCCESS"),"",N6-SUM(I6:M6)) | V6: =IF(OR(N6="",N6=0,L6=""),"",L6/N6) | W6: =IF(OR(N6="",G6="",G6=0),"",N6/(G6/60))
A7: 2 | C7: baseline | D7: baseline | E7: 01min_02 | F7: 1 | T7: =IF(Q7="","",IF(Q7="SUCCESS",1,0)) | U7: =IF(OR(N7="",Q7<>"SUCCESS"),"",N7-SUM(I7:M7)) | V7: =IF(OR(N7="",N7=0,L7=""),"",L7/N7) | W7: =IF(OR(N7="",G7="",G7=0),"",N7/(G7/60))
A8: 3 | C8: baseline | D8: baseline | E8: 01min_03 | F8: 1 | T8: =IF(Q8="","",IF(Q8="SUCCESS",1,0)) | U8: =IF(OR(N8="",Q8<>"SUCCESS"),"",N8-SUM(I8:M8)) | V8: =IF(OR(N8="",N8=0,L8=""),"",L8/N8) | W8: =IF(OR(N8="",G8="",G8=0),"",N8/(G8/60))
A9: 4 | C9: baseline | D9: baseline | E9: 03min_01 | F9: 3 | T9: =IF(Q9="","",IF(Q9="SUCCESS",1,0)) | U9: =IF(OR(N9="",Q9<>"SUCCESS"),"",N9-SUM(I9:M9)) | V9: =IF(OR(N9="",N9=0,L9=""),"",L9/N9) | W9: =IF(OR(N9="",G9="",G9=0),"",N9/(G9/60))
A10: 5 | C10: baseline | D10: baseline | E10: 03min_02 | F10: 3 | T10: =IF(Q10="","",IF(Q10="SUCCESS",1,0)) | U10: =IF(OR(N10="",Q10<>"SUCCESS"),"",N10-SUM(I10:M10)) | V10: =IF(OR(N10="",N10=0,L10=""),"",L10/N10) | W10: =IF(OR(N10="",G10="",G10=0),"",N10/(G10/60))
A11: 6 | C11: baseline | D11: baseline | E11: 03min_03 | F11: 3 | T11: =IF(Q11="","",IF(Q11="SUCCESS",1,0)) | U11: =IF(OR(N11="",Q11<>"SUCCESS"),"",N11-SUM(I11:M11)) | V11: =IF(OR(N11="",N11=0,L11=""),"",L11/N11) | W11: =IF(OR(N11="",G11="",G11=0),"",N11/(G11/60))
A12: 7 | C12: baseline | D12: baseline | E12: 05min_01 | F12: 5 | T12: =IF(Q12="","",IF(Q12="SUCCESS",1,0)) | U12: =IF(OR(N12="",Q12<>"SUCCESS"),"",N12-SUM(I12:M12)) | V12: =IF(OR(N12="",N12=0,L12=""),"",L12/N12) | W12: =IF(OR(N12="",G12="",G12=0),"",N12/(G12/60))
A13: 8 | C13: baseline | D13: baseline | E13: 05min_02 | F13: 5 | T13: =IF(Q13="","",IF(Q13="SUCCESS",1,0)) | U13: =IF(OR(N13="",Q13<>"SUCCESS"),"",N13-SUM(I13:M13)) | V13: =IF(OR(N13="",N13=0,L13=""),"",L13/N13) | W13: =IF(OR(N13="",G13="",G13=0),"",N13/(G13/60))
A14: 9 | C14: baseline | D14: baseline | E14: 05min_03 | F14: 5 | T14: =IF(Q14="","",IF(Q14="SUCCESS",1,0)) | U14: =IF(OR(N14="",Q14<>"SUCCESS"),"",N14-SUM(I14:M14)) | V14: =IF(OR(N14="",N14=0,L14=""),"",L14/N14) | W14: =IF(OR(N14="",G14="",G14=0),"",N14/(G14/60))
A15: 10 | C15: baseline | D15: baseline | E15: 08min_01 | F15: 8 | T15: =IF(Q15="","",IF(Q15="SUCCESS",1,0)) | U15: =IF(OR(N15="",Q15<>"SUCCESS"),"",N15-SUM(I15:M15)) | V15: =IF(OR(N15="",N15=0,L15=""),"",L15/N15) | W15: =IF(OR(N15="",G15="",G15=0),"",N15/(G15/60))
A16: 11 | C16: baseline | D16: baseline | E16: 08min_02 | F16: 8 | T16: =IF(Q16="","",IF(Q16="SUCCESS",1,0)) | U16: =IF(OR(N16="",Q16<>"SUCCESS"),"",N16-SUM(I16:M16)) | V16: =IF(OR(N16="",N16=0,L16=""),"",L16/N16) | W16: =IF(OR(N16="",G16="",G16=0),"",N16/(G16/60))
A17: 12 | C17: baseline | D17: baseline | E17: 08min_03 | F17: 8 | T17: =IF(Q17="","",IF(Q17="SUCCESS",1,0)) | U17: =IF(OR(N17="",Q17<>"SUCCESS"),"",N17-SUM(I17:M17)) | V17: =IF(OR(N17="",N17=0,L17=""),"",L17/N17) | W17: =IF(OR(N17="",G17="",G17=0),"",N17/(G17/60))
... A53: 48 | C53: optimized-fault30 | D53: optimized | E53: 08min_03 | F53: 8 | T53: =IF(Q53="","",IF(Q53="SUCCESS",1,0)) | U53: =IF(OR(N53="",Q53<>"SUCCESS"),"",N53-SUM(I53:M53)) | V53: =IF(OR(N53="",N53=0,L53=""),"",L53/N53) | W53: =IF(OR(N53="",G53="",G53=0),"",N53/(G53/60))
T54: =IF(Q54="","",IF(Q54="SUCCESS",1,0)) | U54: =IF(OR(N54="",Q54<>"SUCCESS"),"",N54-SUM(I54:M54)) | V54: =IF(OR(N54="",N54=0,L54=""),"",L54/N54) | W54: =IF(OR(N54="",G54="",G54=0),"",N54/(G54/60))
T55: =IF(Q55="","",IF(Q55="SUCCESS",1,0)) | U55: =IF(OR(N55="",Q55<>"SUCCESS"),"",N55-SUM(I55:M55)) | V55: =IF(OR(N55="",N55=0,L55=""),"",L55/N55) | W55: =IF(OR(N55="",G55="",G55=0),"",N55/(G55/60))
T56: =IF(Q56="","",IF(Q56="SUCCESS",1,0)) | U56: =IF(OR(N56="",Q56<>"SUCCESS"),"",N56-SUM(I56:M56)) | V56: =IF(OR(N56="",N56=0,L56=""),"",L56/N56) | W56: =IF(OR(N56="",G56="",G56=0),"",N56/(G56/60))
T57: =IF(Q57="","",IF(Q57="SUCCESS",1,0)) | U57: =IF(OR(N57="",Q57<>"SUCCESS"),"",N57-SUM(I57:M57)) | V57: =IF(OR(N57="",N57=0,L57=""),"",L57/N57) | W57: =IF(OR(N57="",G57="",G57=0),"",N57/(G57/60))
T58: =IF(Q58="","",IF(Q58="SUCCESS",1,0)) | U58: =IF(OR(N58="",Q58<>"SUCCESS"),"",N58-SUM(I58:M58)) | V58: =IF(OR(N58="",N58=0,L58=""),"",L58/N58) | W58: =IF(OR(N58="",G58="",G58=0),"",N58/(G58/60))
T59: =IF(Q59="","",IF(Q59="SUCCESS",1,0)) | U59: =IF(OR(N59="",Q59<>"SUCCESS"),"",N59-SUM(I59:M59)) | V59: =IF(OR(N59="",N59=0,L59=""),"",L59/N59) | W59: =IF(OR(N59="",G59="",G59=0),"",N59/(G59/60))
T60: =IF(Q60="","",IF(Q60="SUCCESS",1,0)) | U60: =IF(OR(N60="",Q60<>"SUCCESS"),"",N60-SUM(I60:M60)) | V60: =IF(OR(N60="",N60=0,L60=""),"",L60/N60) | W60: =IF(OR(N60="",G60="",G60=0),"",N60/(G60/60))
T61: =IF(Q61="","",IF(Q61="SUCCESS",1,0)) | U61: =IF(OR(N61="",Q61<>"SUCCESS"),"",N61-SUM(I61:M61)) | V61: =IF(OR(N61="",N61=0,L61=""),"",L61/N61) | W61: =IF(OR(N61="",G61="",G61=0),"",N61/(G61/60))
T62: =IF(Q62="","",IF(Q62="SUCCESS",1,0)) | U62: =IF(OR(N62="",Q62<>"SUCCESS"),"",N62-SUM(I62:M62)) | V62: =IF(OR(N62="",N62=0,L62=""),"",L62/N62) | W62: =IF(OR(N62="",G62="",G62=0),"",N62/(G62/60))
T63: =IF(Q63="","",IF(Q63="SUCCESS",1,0)) | U63: =IF(OR(N63="",Q63<>"SUCCESS"),"",N63-SUM(I63:M63)) | V63: =IF(OR(N63="",N63=0,L63=""),"",L63/N63) | W63: =IF(OR(N63="",G63="",G63=0),"",N63/(G63/60))
T64: =IF(Q64="","",IF(Q64="SUCCESS",1,0)) | U64: =IF(OR(N64="",Q64<>"SUCCESS"),"",N64-SUM(I64:M64)) | V64: =IF(OR(N64="",N64=0,L64=""),"",L64/N64) | W64: =IF(OR(N64="",G64="",G64=0),"",N64/(G64/60))
T65: =IF(Q65="","",IF(Q65="SUCCESS",1,0)) | U65: =IF(OR(N65="",Q65<>"SUCCESS"),"",N65-SUM(I65:M65)) | V65: =IF(OR(N65="",N65=0,L65=""),"",L65/N65) | W65: =IF(OR(N65="",G65="",G65=0),"",N65/(G65/60))
... T505: =IF(Q505="","",IF(Q505="SUCCESS",1,0)) | U505: =IF(OR(N505="",Q505<>"SUCCESS"),"",N505-SUM(I505:M505)) | V505: =IF(OR(N505="",N505=0,L505=""),"",L505/N505) | W505: =IF(OR(N505="",G505="",G505=0),"",N505/(G505/60))

Sheet Ringkasan Latensi
A1: Ringkasan Latensi per Durasi Video
A2: Statistik waktu hanya memakai baris berstatus SUCCESS. Ganti Label A / Label B (sel kuning) untuk membandingkan fase lain, mis. baseline-fault30 vs optimized-fault30.
B4: Label A | C4: baseline
B5: Label B | C5: optimized
B7: ="Tabel A: "&$C$4
B8: Durasi Target (mnt) | C8: n (diuji) | D8: Sukses | E8: Tingkat Gagal | F8: Rata-rata Total Server (dtk) | G8: SD (dtk) | H8: Median (dtk) | I8: P95 (dtk) | J8: Min (dtk) | K8: Maks (dtk) | L8: Terima File (dtk) | M8: Upload Gemini (dtk) | N8: Tunggu ACTIVE (dtk) | O8: generateContent (dtk) | P8: Simpan DB (dtk) | Q8: Lain-lain (dtk) | R8: Rata-rata Total Dirasakan User (dtk) | S8: Latensi per Menit Video (dtk/mnt) | T8: Rata-rata Percobaan generate
B9: 1 | C9: =SUMPRODUCT(('Data Pengujian'!$C$6:$C$505=$C$4)*('Data Pengujian'!$F$6:$F$505=$B9)*('Data Pengujian'!$Q$6:$Q$505<>"")) | D9: =COUNTIFS('Data Pengujian'!$C$6:$C$505,$C$4,'Data Pengujian'!$F$6:$F$505,$B9,'Data Pengujian'!$Q$6:$Q$505,"SUCCESS") | E9: =IF(C9=0,"",1-D9/C9) | F9: =IFERROR(AVERAGEIFS('Data Pengujian'!$N$6:$N$505,'Data Pengujian'!$C$6:$C$505,$C$4,'Data Pengujian'!$F$6:$F$505,$B9,'Data Pengujian'!$Q$6:$Q$505,"SUCCESS"),"") | G9: =IF(SUMPRODUCT(('Data Pengujian'!$C$6:$C$505=$C$4)*('Data Pengujian'!$F$6:$F$505=$B9)*('Data Pengujian'!$Q$6:$Q$505="SUCCESS")*('Data Pengujian'!$N$6:$N$505<>""))<2,"",SQRT(SUMPRODUCT(('Data Pengujian'!$C$6:$C$505=$C$4)*('Data Pengujian'!$F$6:$F$505=$B9)*('Data Pengujian'!$Q$6:$Q$505="SUCCESS")*('Data Pengujian'!$N$6:$N$505<>"")*('Data Pengujian'!$N$6:$N$505-F9)^2)/(SUMPRODUCT(('Data Pengujian'!$C$6:$C$505=$C$4)*('Data Pengujian'!$F$6:$F$505=$B9)*('Data Pengujian'!$Q$6:$Q$505="SUCCESS")*('Data Pengujian'!$N$6:$N$505<>""))-1))) | H9: {=IFERROR(MEDIAN(IF(('Data Pengujian'!$C$6:$C$505=$C$4)*('Data Pengujian'!$F$6:$F$505=$B9)*('Data Pengujian'!$Q$6:$Q$505="SUCCESS")*('Data Pengujian'!$N$6:$N$505<>""),'Data Pengujian'!$N$6:$N$505)),"")} | I9: {=IFERROR(PERCENTILE(IF(('Data Pengujian'!$C$6:$C$505=$C$4)*('Data Pengujian'!$F$6:$F$505=$B9)*('Data Pengujian'!$Q$6:$Q$505="SUCCESS")*('Data Pengujian'!$N$6:$N$505<>""),'Data Pengujian'!$N$6:$N$505),0.95),"")} | J9: {=IF(SUMPRODUCT(('Data Pengujian'!$C$6:$C$505=$C$4)*('Data Pengujian'!$F$6:$F$505=$B9)*('Data Pengujian'!$Q$6:$Q$505="SUCCESS")*('Data Pengujian'!$N$6:$N$505<>""))=0,"",MIN(IF(('Data Pengujian'!$C$6:$C$505=$C$4)*('Data Pengujian'!$F$6:$F$505=$B9)*('Data Pengujian'!$Q$6:$Q$505="SUCCESS")*('Data Pengujian'!$N$6:$N$505<>""),'Data Pengujian'!$N$6:$N$505)))} | K9: {=IF(SUMPRODUCT(('Data Pengujian'!$C$6:$C$505=$C$4)*('Data Pengujian'!$F$6:$F$505=$B9)*('Data Pengujian'!$Q$6:$Q$505="SUCCESS")*('Data Pengujian'!$N$6:$N$505<>""))=0,"",MAX(IF(('Data Pengujian'!$C$6:$C$505=$C$4)*('Data Pengujian'!$F$6:$F$505=$B9)*('Data Pengujian'!$Q$6:$Q$505="SUCCESS")*('Data Pengujian'!$N$6:$N$505<>""),'Data Pengujian'!$N$6:$N$505)))} | L9: =IFERROR(AVERAGEIFS('Data Pengujian'!$I$6:$I$505,'Data Pengujian'!$C$6:$C$505,$C$4,'Data Pengujian'!$F$6:$F$505,$B9,'Data Pengujian'!$Q$6:$Q$505,"SUCCESS"),"") | M9: =IFERROR(AVERAGEIFS('Data Pengujian'!$J$6:$J$505,'Data Pengujian'!$C$6:$C$505,$C$4,'Data Pengujian'!$F$6:$F$505,$B9,'Data Pengujian'!$Q$6:$Q$505,"SUCCESS"),"") | N9: =IFERROR(AVERAGEIFS('Data Pengujian'!$K$6:$K$505,'Data Pengujian'!$C$6:$C$505,$C$4,'Data Pengujian'!$F$6:$F$505,$B9,'Data Pengujian'!$Q$6:$Q$505,"SUCCESS"),"") | O9: =IFERROR(AVERAGEIFS('Data Pengujian'!$L$6:$L$505,'Data Pengujian'!$C$6:$C$505,$C$4,'Data Pengujian'!$F$6:$F$505,$B9,'Data Pengujian'!$Q$6:$Q$505,"SUCCESS"),"") | P9: =IFERROR(AVERAGEIFS('Data Pengujian'!$M$6:$M$505,'Data Pengujian'!$C$6:$C$505,$C$4,'Data Pengujian'!$F$6:$F$505,$B9,'Data Pengujian'!$Q$6:$Q$505,"SUCCESS"),"") | Q9: =IFERROR(AVERAGEIFS('Data Pengujian'!$U$6:$U$505,'Data Pengujian'!$C$6:$C$505,$C$4,'Data Pengujian'!$F$6:$F$505,$B9,'Data Pengujian'!$Q$6:$Q$505,"SUCCESS"),"") | R9: =IFERROR(AVERAGEIFS('Data Pengujian'!$O$6:$O$505,'Data Pengujian'!$C$6:$C$505,$C$4,'Data Pengujian'!$F$6:$F$505,$B9,'Data Pengujian'!$Q$6:$Q$505,"SUCCESS"),"") | S9: =IFERROR(AVERAGEIFS('Data Pengujian'!$W$6:$W$505,'Data Pengujian'!$C$6:$C$505,$C$4,'Data Pengujian'!$F$6:$F$505,$B9,'Data Pengujian'!$Q$6:$Q$505,"SUCCESS"),"") | T9: =IFERROR(SUMPRODUCT(('Data Pengujian'!$C$6:$C$505=$C$4)*('Data Pengujian'!$F$6:$F$505=$B9)*('Data Pengujian'!$Q$6:$Q$505<>"")*'Data Pengujian'!$P$6:$P$505)/SUMPRODUCT(('Data Pengujian'!$C$6:$C$505=$C$4)*('Data Pengujian'!$F$6:$F$505=$B9)*('Data Pengujian'!$Q$6:$Q$505<>"")*('Data Pengujian'!$P$6:$P$505<>"")),"")
B10: 3 | C10: =SUMPRODUCT(('Data Pengujian'!$C$6:$C$505=$C$4)*('Data Pengujian'!$F$6:$F$505=$B10)*('Data Pengujian'!$Q$6:$Q$505<>"")) | D10: =COUNTIFS('Data Pengujian'!$C$6:$C$505,$C$4,'Data Pengujian'!$F$6:$F$505,$B10,'Data Pengujian'!$Q$6:$Q$505,"SUCCESS") | E10: =IF(C10=0,"",1-D10/C10) | F10: =IFERROR(AVERAGEIFS('Data Pengujian'!$N$6:$N$505,'Data Pengujian'!$C$6:$C$505,$C$4,'Data Pengujian'!$F$6:$F$505,$B10,'Data Pengujian'!$Q$6:$Q$505,"SUCCESS"),"") | G10: =IF(SUMPRODUCT(('Data Pengujian'!$C$6:$C$505=$C$4)*('Data Pengujian'!$F$6:$F$505=$B10)*('Data Pengujian'!$Q$6:$Q$505="SUCCESS")*('Data Pengujian'!$N$6:$N$505<>""))<2,"",SQRT(SUMPRODUCT(('Data Pengujian'!$C$6:$C$505=$C$4)*('Data Pengujian'!$F$6:$F$505=$B10)*('Data Pengujian'!$Q$6:$Q$505="SUCCESS")*('Data Pengujian'!$N$6:$N$505<>"")*('Data Pengujian'!$N$6:$N$505-F10)^2)/(SUMPRODUCT(('Data Pengujian'!$C$6:$C$505=$C$4)*('Data Pengujian'!$F$6:$F$505=$B10)*('Data Pengujian'!$Q$6:$Q$505="SUCCESS")*('Data Pengujian'!$N$6:$N$505<>""))-1))) | H10: {=IFERROR(MEDIAN(IF(('Data Pengujian'!$C$6:$C$505=$C$4)*('Data Pengujian'!$F$6:$F$505=$B10)*('Data Pengujian'!$Q$6:$Q$505="SUCCESS")*('Data Pengujian'!$N$6:$N$505<>""),'Data Pengujian'!$N$6:$N$505)),"")} | I10: {=IFERROR(PERCENTILE(IF(('Data Pengujian'!$C$6:$C$505=$C$4)*('Data Pengujian'!$F$6:$F$505=$B10)*('Data Pengujian'!$Q$6:$Q$505="SUCCESS")*('Data Pengujian'!$N$6:$N$505<>""),'Data Pengujian'!$N$6:$N$505),0.95),"")} | J10: {=IF(SUMPRODUCT(('Data Pengujian'!$C$6:$C$505=$C$4)*('Data Pengujian'!$F$6:$F$505=$B10)*('Data Pengujian'!$Q$6:$Q$505="SUCCESS")*('Data Pengujian'!$N$6:$N$505<>""))=0,"",MIN(IF(('Data Pengujian'!$C$6:$C$505=$C$4)*('Data Pengujian'!$F$6:$F$505=$B10)*('Data Pengujian'!$Q$6:$Q$505="SUCCESS")*('Data Pengujian'!$N$6:$N$505<>""),'Data Pengujian'!$N$6:$N$505)))} | K10: {=IF(SUMPRODUCT(('Data Pengujian'!$C$6:$C$505=$C$4)*('Data Pengujian'!$F$6:$F$505=$B10)*('Data Pengujian'!$Q$6:$Q$505="SUCCESS")*('Data Pengujian'!$N$6:$N$505<>""))=0,"",MAX(IF(('Data Pengujian'!$C$6:$C$505=$C$4)*('Data Pengujian'!$F$6:$F$505=$B10)*('Data Pengujian'!$Q$6:$Q$505="SUCCESS")*('Data Pengujian'!$N$6:$N$505<>""),'Data Pengujian'!$N$6:$N$505)))} | L10: =IFERROR(AVERAGEIFS('Data Pengujian'!$I$6:$I$505,'Data Pengujian'!$C$6:$C$505,$C$4,'Data Pengujian'!$F$6:$F$505,$B10,'Data Pengujian'!$Q$6:$Q$505,"SUCCESS"),"") | M10: =IFERROR(AVERAGEIFS('Data Pengujian'!$J$6:$J$505,'Data Pengujian'!$C$6:$C$505,$C$4,'Data Pengujian'!$F$6:$F$505,$B10,'Data Pengujian'!$Q$6:$Q$505,"SUCCESS"),"") | N10: =IFERROR(AVERAGEIFS('Data Pengujian'!$K$6:$K$505,'Data Pengujian'!$C$6:$C$505,$C$4,'Data Pengujian'!$F$6:$F$505,$B10,'Data Pengujian'!$Q$6:$Q$505,"SUCCESS"),"") | O10: =IFERROR(AVERAGEIFS('Data Pengujian'!$L$6:$L$505,'Data Pengujian'!$C$6:$C$505,$C$4,'Data Pengujian'!$F$6:$F$505,$B10,'Data Pengujian'!$Q$6:$Q$505,"SUCCESS"),"") | P10: =IFERROR(AVERAGEIFS('Data Pengujian'!$M$6:$M$505,'Data Pengujian'!$C$6:$C$505,$C$4,'Data Pengujian'!$F$6:$F$505,$B10,'Data Pengujian'!$Q$6:$Q$505,"SUCCESS"),"") | Q10: =IFERROR(AVERAGEIFS('Data Pengujian'!$U$6:$U$505,'Data Pengujian'!$C$6:$C$505,$C$4,'Data Pengujian'!$F$6:$F$505,$B10,'Data Pengujian'!$Q$6:$Q$505,"SUCCESS"),"") | R10: =IFERROR(AVERAGEIFS('Data Pengujian'!$O$6:$O$505,'Data Pengujian'!$C$6:$C$505,$C$4,'Data Pengujian'!$F$6:$F$505,$B10,'Data Pengujian'!$Q$6:$Q$505,"SUCCESS"),"") | S10: =IFERROR(AVERAGEIFS('Data Pengujian'!$W$6:$W$505,'Data Pengujian'!$C$6:$C$505,$C$4,'Data Pengujian'!$F$6:$F$505,$B10,'Data Pengujian'!$Q$6:$Q$505,"SUCCESS"),"") | T10: =IFERROR(SUMPRODUCT(('Data Pengujian'!$C$6:$C$505=$C$4)*('Data Pengujian'!$F$6:$F$505=$B10)*('Data Pengujian'!$Q$6:$Q$505<>"")*'Data Pengujian'!$P$6:$P$505)/SUMPRODUCT(('Data Pengujian'!$C$6:$C$505=$C$4)*('Data Pengujian'!$F$6:$F$505=$B10)*('Data Pengujian'!$Q$6:$Q$505<>"")*('Data Pengujian'!$P$6:$P$505<>"")),"")
B11: 5 | C11: =SUMPRODUCT(('Data Pengujian'!$C$6:$C$505=$C$4)*('Data Pengujian'!$F$6:$F$505=$B11)*('Data Pengujian'!$Q$6:$Q$505<>"")) | D11: =COUNTIFS('Data Pengujian'!$C$6:$C$505,$C$4,'Data Pengujian'!$F$6:$F$505,$B11,'Data Pengujian'!$Q$6:$Q$505,"SUCCESS") | E11: =IF(C11=0,"",1-D11/C11) | F11: =IFERROR(AVERAGEIFS('Data Pengujian'!$N$6:$N$505,'Data Pengujian'!$C$6:$C$505,$C$4,'Data Pengujian'!$F$6:$F$505,$B11,'Data Pengujian'!$Q$6:$Q$505,"SUCCESS"),"") | G11: =IF(SUMPRODUCT(('Data Pengujian'!$C$6:$C$505=$C$4)*('Data Pengujian'!$F$6:$F$505=$B11)*('Data Pengujian'!$Q$6:$Q$505="SUCCESS")*('Data Pengujian'!$N$6:$N$505<>""))<2,"",SQRT(SUMPRODUCT(('Data Pengujian'!$C$6:$C$505=$C$4)*('Data Pengujian'!$F$6:$F$505=$B11)*('Data Pengujian'!$Q$6:$Q$505="SUCCESS")*('Data Pengujian'!$N$6:$N$505<>"")*('Data Pengujian'!$N$6:$N$505-F11)^2)/(SUMPRODUCT(('Data Pengujian'!$C$6:$C$505=$C$4)*('Data Pengujian'!$F$6:$F$505=$B11)*('Data Pengujian'!$Q$6:$Q$505="SUCCESS")*('Data Pengujian'!$N$6:$N$505<>""))-1))) | H11: {=IFERROR(MEDIAN(IF(('Data Pengujian'!$C$6:$C$505=$C$4)*('Data Pengujian'!$F$6:$F$505=$B11)*('Data Pengujian'!$Q$6:$Q$505="SUCCESS")*('Data Pengujian'!$N$6:$N$505<>""),'Data Pengujian'!$N$6:$N$505)),"")} | I11: {=IFERROR(PERCENTILE(IF(('Data Pengujian'!$C$6:$C$505=$C$4)*('Data Pengujian'!$F$6:$F$505=$B11)*('Data Pengujian'!$Q$6:$Q$505="SUCCESS")*('Data Pengujian'!$N$6:$N$505<>""),'Data Pengujian'!$N$6:$N$505),0.95),"")} | J11: {=IF(SUMPRODUCT(('Data Pengujian'!$C$6:$C$505=$C$4)*('Data Pengujian'!$F$6:$F$505=$B11)*('Data Pengujian'!$Q$6:$Q$505="SUCCESS")*('Data Pengujian'!$N$6:$N$505<>""))=0,"",MIN(IF(('Data Pengujian'!$C$6:$C$505=$C$4)*('Data Pengujian'!$F$6:$F$505=$B11)*('Data Pengujian'!$Q$6:$Q$505="SUCCESS")*('Data Pengujian'!$N$6:$N$505<>""),'Data Pengujian'!$N$6:$N$505)))} | K11: {=IF(SUMPRODUCT(('Data Pengujian'!$C$6:$C$505=$C$4)*('Data Pengujian'!$F$6:$F$505=$B11)*('Data Pengujian'!$Q$6:$Q$505="SUCCESS")*('Data Pengujian'!$N$6:$N$505<>""))=0,"",MAX(IF(('Data Pengujian'!$C$6:$C$505=$C$4)*('Data Pengujian'!$F$6:$F$505=$B11)*('Data Pengujian'!$Q$6:$Q$505="SUCCESS")*('Data Pengujian'!$N$6:$N$505<>""),'Data Pengujian'!$N$6:$N$505)))} | L11: =IFERROR(AVERAGEIFS('Data Pengujian'!$I$6:$I$505,'Data Pengujian'!$C$6:$C$505,$C$4,'Data Pengujian'!$F$6:$F$505,$B11,'Data Pengujian'!$Q$6:$Q$505,"SUCCESS"),"") | M11: =IFERROR(AVERAGEIFS('Data Pengujian'!$J$6:$J$505,'Data Pengujian'!$C$6:$C$505,$C$4,'Data Pengujian'!$F$6:$F$505,$B11,'Data Pengujian'!$Q$6:$Q$505,"SUCCESS"),"") | N11: =IFERROR(AVERAGEIFS('Data Pengujian'!$K$6:$K$505,'Data Pengujian'!$C$6:$C$505,$C$4,'Data Pengujian'!$F$6:$F$505,$B11,'Data Pengujian'!$Q$6:$Q$505,"SUCCESS"),"") | O11: =IFERROR(AVERAGEIFS('Data Pengujian'!$L$6:$L$505,'Data Pengujian'!$C$6:$C$505,$C$4,'Data Pengujian'!$F$6:$F$505,$B11,'Data Pengujian'!$Q$6:$Q$505,"SUCCESS"),"") | P11: =IFERROR(AVERAGEIFS('Data Pengujian'!$M$6:$M$505,'Data Pengujian'!$C$6:$C$505,$C$4,'Data Pengujian'!$F$6:$F$505,$B11,'Data Pengujian'!$Q$6:$Q$505,"SUCCESS"),"") | Q11: =IFERROR(AVERAGEIFS('Data Pengujian'!$U$6:$U$505,'Data Pengujian'!$C$6:$C$505,$C$4,'Data Pengujian'!$F$6:$F$505,$B11,'Data Pengujian'!$Q$6:$Q$505,"SUCCESS"),"") | R11: =IFERROR(AVERAGEIFS('Data Pengujian'!$O$6:$O$505,'Data Pengujian'!$C$6:$C$505,$C$4,'Data Pengujian'!$F$6:$F$505,$B11,'Data Pengujian'!$Q$6:$Q$505,"SUCCESS"),"") | S11: =IFERROR(AVERAGEIFS('Data Pengujian'!$W$6:$W$505,'Data Pengujian'!$C$6:$C$505,$C$4,'Data Pengujian'!$F$6:$F$505,$B11,'Data Pengujian'!$Q$6:$Q$505,"SUCCESS"),"") | T11: =IFERROR(SUMPRODUCT(('Data Pengujian'!$C$6:$C$505=$C$4)*('Data Pengujian'!$F$6:$F$505=$B11)*('Data Pengujian'!$Q$6:$Q$505<>"")*'Data Pengujian'!$P$6:$P$505)/SUMPRODUCT(('Data Pengujian'!$C$6:$C$505=$C$4)*('Data Pengujian'!$F$6:$F$505=$B11)*('Data Pengujian'!$Q$6:$Q$505<>"")*('Data Pengujian'!$P$6:$P$505<>"")),"")
B12: 8 | C12: =SUMPRODUCT(('Data Pengujian'!$C$6:$C$505=$C$4)*('Data Pengujian'!$F$6:$F$505=$B12)*('Data Pengujian'!$Q$6:$Q$505<>"")) | D12: =COUNTIFS('Data Pengujian'!$C$6:$C$505,$C$4,'Data Pengujian'!$F$6:$F$505,$B12,'Data Pengujian'!$Q$6:$Q$505,"SUCCESS") | E12: =IF(C12=0,"",1-D12/C12) | F12: =IFERROR(AVERAGEIFS('Data Pengujian'!$N$6:$N$505,'Data Pengujian'!$C$6:$C$505,$C$4,'Data Pengujian'!$F$6:$F$505,$B12,'Data Pengujian'!$Q$6:$Q$505,"SUCCESS"),"") | G12: =IF(SUMPRODUCT(('Data Pengujian'!$C$6:$C$505=$C$4)*('Data Pengujian'!$F$6:$F$505=$B12)*('Data Pengujian'!$Q$6:$Q$505="SUCCESS")*('Data Pengujian'!$N$6:$N$505<>""))<2,"",SQRT(SUMPRODUCT(('Data Pengujian'!$C$6:$C$505=$C$4)*('Data Pengujian'!$F$6:$F$505=$B12)*('Data Pengujian'!$Q$6:$Q$505="SUCCESS")*('Data Pengujian'!$N$6:$N$505<>"")*('Data Pengujian'!$N$6:$N$505-F12)^2)/(SUMPRODUCT(('Data Pengujian'!$C$6:$C$505=$C$4)*('Data Pengujian'!$F$6:$F$505=$B12)*('Data Pengujian'!$Q$6:$Q$505="SUCCESS")*('Data Pengujian'!$N$6:$N$505<>""))-1))) | H12: {=IFERROR(MEDIAN(IF(('Data Pengujian'!$C$6:$C$505=$C$4)*('Data Pengujian'!$F$6:$F$505=$B12)*('Data Pengujian'!$Q$6:$Q$505="SUCCESS")*('Data Pengujian'!$N$6:$N$505<>""),'Data Pengujian'!$N$6:$N$505)),"")} | I12: {=IFERROR(PERCENTILE(IF(('Data Pengujian'!$C$6:$C$505=$C$4)*('Data Pengujian'!$F$6:$F$505=$B12)*('Data Pengujian'!$Q$6:$Q$505="SUCCESS")*('Data Pengujian'!$N$6:$N$505<>""),'Data Pengujian'!$N$6:$N$505),0.95),"")} | J12: {=IF(SUMPRODUCT(('Data Pengujian'!$C$6:$C$505=$C$4)*('Data Pengujian'!$F$6:$F$505=$B12)*('Data Pengujian'!$Q$6:$Q$505="SUCCESS")*('Data Pengujian'!$N$6:$N$505<>""))=0,"",MIN(IF(('Data Pengujian'!$C$6:$C$505=$C$4)*('Data Pengujian'!$F$6:$F$505=$B12)*('Data Pengujian'!$Q$6:$Q$505="SUCCESS")*('Data Pengujian'!$N$6:$N$505<>""),'Data Pengujian'!$N$6:$N$505)))} | K12: {=IF(SUMPRODUCT(('Data Pengujian'!$C$6:$C$505=$C$4)*('Data Pengujian'!$F$6:$F$505=$B12)*('Data Pengujian'!$Q$6:$Q$505="SUCCESS")*('Data Pengujian'!$N$6:$N$505<>""))=0,"",MAX(IF(('Data Pengujian'!$C$6:$C$505=$C$4)*('Data Pengujian'!$F$6:$F$505=$B12)*('Data Pengujian'!$Q$6:$Q$505="SUCCESS")*('Data Pengujian'!$N$6:$N$505<>""),'Data Pengujian'!$N$6:$N$505)))} | L12: =IFERROR(AVERAGEIFS('Data Pengujian'!$I$6:$I$505,'Data Pengujian'!$C$6:$C$505,$C$4,'Data Pengujian'!$F$6:$F$505,$B12,'Data Pengujian'!$Q$6:$Q$505,"SUCCESS"),"") | M12: =IFERROR(AVERAGEIFS('Data Pengujian'!$J$6:$J$505,'Data Pengujian'!$C$6:$C$505,$C$4,'Data Pengujian'!$F$6:$F$505,$B12,'Data Pengujian'!$Q$6:$Q$505,"SUCCESS"),"") | N12: =IFERROR(AVERAGEIFS('Data Pengujian'!$K$6:$K$505,'Data Pengujian'!$C$6:$C$505,$C$4,'Data Pengujian'!$F$6:$F$505,$B12,'Data Pengujian'!$Q$6:$Q$505,"SUCCESS"),"") | O12: =IFERROR(AVERAGEIFS('Data Pengujian'!$L$6:$L$505,'Data Pengujian'!$C$6:$C$505,$C$4,'Data Pengujian'!$F$6:$F$505,$B12,'Data Pengujian'!$Q$6:$Q$505,"SUCCESS"),"") | P12: =IFERROR(AVERAGEIFS('Data Pengujian'!$M$6:$M$505,'Data Pengujian'!$C$6:$C$505,$C$4,'Data Pengujian'!$F$6:$F$505,$B12,'Data Pengujian'!$Q$6:$Q$505,"SUCCESS"),"") | Q12: =IFERROR(AVERAGEIFS('Data Pengujian'!$U$6:$U$505,'Data Pengujian'!$C$6:$C$505,$C$4,'Data Pengujian'!$F$6:$F$505,$B12,'Data Pengujian'!$Q$6:$Q$505,"SUCCESS"),"") | R12: =IFERROR(AVERAGEIFS('Data Pengujian'!$O$6:$O$505,'Data Pengujian'!$C$6:$C$505,$C$4,'Data Pengujian'!$F$6:$F$505,$B12,'Data Pengujian'!$Q$6:$Q$505,"SUCCESS"),"") | S12: =IFERROR(AVERAGEIFS('Data Pengujian'!$W$6:$W$505,'Data Pengujian'!$C$6:$C$505,$C$4,'Data Pengujian'!$F$6:$F$505,$B12,'Data Pengujian'!$Q$6:$Q$505,"SUCCESS"),"") | T12: =IFERROR(SUMPRODUCT(('Data Pengujian'!$C$6:$C$505=$C$4)*('Data Pengujian'!$F$6:$F$505=$B12)*('Data Pengujian'!$Q$6:$Q$505<>"")*'Data Pengujian'!$P$6:$P$505)/SUMPRODUCT(('Data Pengujian'!$C$6:$C$505=$C$4)*('Data Pengujian'!$F$6:$F$505=$B12)*('Data Pengujian'!$Q$6:$Q$505<>"")*('Data Pengujian'!$P$6:$P$505<>"")),"")
B13: Semua | C13: =SUMPRODUCT(('Data Pengujian'!$C$6:$C$505=$C$4)*('Data Pengujian'!$Q$6:$Q$505<>"")) | D13: =COUNTIFS('Data Pengujian'!$C$6:$C$505,$C$4,'Data Pengujian'!$Q$6:$Q$505,"SUCCESS") | E13: =IF(C13=0,"",1-D13/C13) | F13: =IFERROR(AVERAGEIFS('Data Pengujian'!$N$6:$N$505,'Data Pengujian'!$C$6:$C$505,$C$4,'Data Pengujian'!$Q$6:$Q$505,"SUCCESS"),"") | G13: =IF(SUMPRODUCT(('Data Pengujian'!$C$6:$C$505=$C$4)*('Data Pengujian'!$Q$6:$Q$505="SUCCESS")*('Data Pengujian'!$N$6:$N$505<>""))<2,"",SQRT(SUMPRODUCT(('Data Pengujian'!$C$6:$C$505=$C$4)*('Data Pengujian'!$Q$6:$Q$505="SUCCESS")*('Data Pengujian'!$N$6:$N$505<>"")*('Data Pengujian'!$N$6:$N$505-F13)^2)/(SUMPRODUCT(('Data Pengujian'!$C$6:$C$505=$C$4)*('Data Pengujian'!$Q$6:$Q$505="SUCCESS")*('Data Pengujian'!$N$6:$N$505<>""))-1))) | H13: {=IFERROR(MEDIAN(IF(('Data Pengujian'!$C$6:$C$505=$C$4)*('Data Pengujian'!$Q$6:$Q$505="SUCCESS")*('Data Pengujian'!$N$6:$N$505<>""),'Data Pengujian'!$N$6:$N$505)),"")} | I13: {=IFERROR(PERCENTILE(IF(('Data Pengujian'!$C$6:$C$505=$C$4)*('Data Pengujian'!$Q$6:$Q$505="SUCCESS")*('Data Pengujian'!$N$6:$N$505<>""),'Data Pengujian'!$N$6:$N$505),0.95),"")} | J13: {=IF(SUMPRODUCT(('Data Pengujian'!$C$6:$C$505=$C$4)*('Data Pengujian'!$Q$6:$Q$505="SUCCESS")*('Data Pengujian'!$N$6:$N$505<>""))=0,"",MIN(IF(('Data Pengujian'!$C$6:$C$505=$C$4)*('Data Pengujian'!$Q$6:$Q$505="SUCCESS")*('Data Pengujian'!$N$6:$N$505<>""),'Data Pengujian'!$N$6:$N$505)))} | K13: {=IF(SUMPRODUCT(('Data Pengujian'!$C$6:$C$505=$C$4)*('Data Pengujian'!$Q$6:$Q$505="SUCCESS")*('Data Pengujian'!$N$6:$N$505<>""))=0,"",MAX(IF(('Data Pengujian'!$C$6:$C$505=$C$4)*('Data Pengujian'!$Q$6:$Q$505="SUCCESS")*('Data Pengujian'!$N$6:$N$505<>""),'Data Pengujian'!$N$6:$N$505)))} | L13: =IFERROR(AVERAGEIFS('Data Pengujian'!$I$6:$I$505,'Data Pengujian'!$C$6:$C$505,$C$4,'Data Pengujian'!$Q$6:$Q$505,"SUCCESS"),"") | M13: =IFERROR(AVERAGEIFS('Data Pengujian'!$J$6:$J$505,'Data Pengujian'!$C$6:$C$505,$C$4,'Data Pengujian'!$Q$6:$Q$505,"SUCCESS"),"") | N13: =IFERROR(AVERAGEIFS('Data Pengujian'!$K$6:$K$505,'Data Pengujian'!$C$6:$C$505,$C$4,'Data Pengujian'!$Q$6:$Q$505,"SUCCESS"),"") | O13: =IFERROR(AVERAGEIFS('Data Pengujian'!$L$6:$L$505,'Data Pengujian'!$C$6:$C$505,$C$4,'Data Pengujian'!$Q$6:$Q$505,"SUCCESS"),"") | P13: =IFERROR(AVERAGEIFS('Data Pengujian'!$M$6:$M$505,'Data Pengujian'!$C$6:$C$505,$C$4,'Data Pengujian'!$Q$6:$Q$505,"SUCCESS"),"") | Q13: =IFERROR(AVERAGEIFS('Data Pengujian'!$U$6:$U$505,'Data Pengujian'!$C$6:$C$505,$C$4,'Data Pengujian'!$Q$6:$Q$505,"SUCCESS"),"") | R13: =IFERROR(AVERAGEIFS('Data Pengujian'!$O$6:$O$505,'Data Pengujian'!$C$6:$C$505,$C$4,'Data Pengujian'!$Q$6:$Q$505,"SUCCESS"),"") | S13: =IFERROR(AVERAGEIFS('Data Pengujian'!$W$6:$W$505,'Data Pengujian'!$C$6:$C$505,$C$4,'Data Pengujian'!$Q$6:$Q$505,"SUCCESS"),"") | T13: =IFERROR(SUMPRODUCT(('Data Pengujian'!$C$6:$C$505=$C$4)*('Data Pengujian'!$Q$6:$Q$505<>"")*'Data Pengujian'!$P$6:$P$505)/SUMPRODUCT(('Data Pengujian'!$C$6:$C$505=$C$4)*('Data Pengujian'!$Q$6:$Q$505<>"")*('Data Pengujian'!$P$6:$P$505<>"")),"")
B16: ="Tabel B: "&$C$5
B17: Durasi Target (mnt) | C17: n (diuji) | D17: Sukses | E17: Tingkat Gagal | F17: Rata-rata Total Server (dtk) | G17: SD (dtk) | H17: Median (dtk) | I17: P95 (dtk) | J17: Min (dtk) | K17: Maks (dtk) | L17: Terima File (dtk) | M17: Upload Gemini (dtk) | N17: Tunggu ACTIVE (dtk) | O17: generateContent (dtk) | P17: Simpan DB (dtk) | Q17: Lain-lain (dtk) | R17: Rata-rata Total Dirasakan User (dtk) | S17: Latensi per Menit Video (dtk/mnt) | T17: Rata-rata Percobaan generate
B18: 1 | C18: =SUMPRODUCT(('Data Pengujian'!$C$6:$C$505=$C$5)*('Data Pengujian'!$F$6:$F$505=$B18)*('Data Pengujian'!$Q$6:$Q$505<>"")) | D18: =COUNTIFS('Data Pengujian'!$C$6:$C$505,$C$5,'Data Pengujian'!$F$6:$F$505,$B18,'Data Pengujian'!$Q$6:$Q$505,"SUCCESS") | E18: =IF(C18=0,"",1-D18/C18) | F18: =IFERROR(AVERAGEIFS('Data Pengujian'!$N$6:$N$505,'Data Pengujian'!$C$6:$C$505,$C$5,'Data Pengujian'!$F$6:$F$505,$B18,'Data Pengujian'!$Q$6:$Q$505,"SUCCESS"),"") | G18: =IF(SUMPRODUCT(('Data Pengujian'!$C$6:$C$505=$C$5)*('Data Pengujian'!$F$6:$F$505=$B18)*('Data Pengujian'!$Q$6:$Q$505="SUCCESS")*('Data Pengujian'!$N$6:$N$505<>""))<2,"",SQRT(SUMPRODUCT(('Data Pengujian'!$C$6:$C$505=$C$5)*('Data Pengujian'!$F$6:$F$505=$B18)*('Data Pengujian'!$Q$6:$Q$505="SUCCESS")*('Data Pengujian'!$N$6:$N$505<>"")*('Data Pengujian'!$N$6:$N$505-F18)^2)/(SUMPRODUCT(('Data Pengujian'!$C$6:$C$505=$C$5)*('Data Pengujian'!$F$6:$F$505=$B18)*('Data Pengujian'!$Q$6:$Q$505="SUCCESS")*('Data Pengujian'!$N$6:$N$505<>""))-1))) | H18: {=IFERROR(MEDIAN(IF(('Data Pengujian'!$C$6:$C$505=$C$5)*('Data Pengujian'!$F$6:$F$505=$B18)*('Data Pengujian'!$Q$6:$Q$505="SUCCESS")*('Data Pengujian'!$N$6:$N$505<>""),'Data Pengujian'!$N$6:$N$505)),"")} | I18: {=IFERROR(PERCENTILE(IF(('Data Pengujian'!$C$6:$C$505=$C$5)*('Data Pengujian'!$F$6:$F$505=$B18)*('Data Pengujian'!$Q$6:$Q$505="SUCCESS")*('Data Pengujian'!$N$6:$N$505<>""),'Data Pengujian'!$N$6:$N$505),0.95),"")} | J18: {=IF(SUMPRODUCT(('Data Pengujian'!$C$6:$C$505=$C$5)*('Data Pengujian'!$F$6:$F$505=$B18)*('Data Pengujian'!$Q$6:$Q$505="SUCCESS")*('Data Pengujian'!$N$6:$N$505<>""))=0,"",MIN(IF(('Data Pengujian'!$C$6:$C$505=$C$5)*('Data Pengujian'!$F$6:$F$505=$B18)*('Data Pengujian'!$Q$6:$Q$505="SUCCESS")*('Data Pengujian'!$N$6:$N$505<>""),'Data Pengujian'!$N$6:$N$505)))} | K18: {=IF(SUMPRODUCT(('Data Pengujian'!$C$6:$C$505=$C$5)*('Data Pengujian'!$F$6:$F$505=$B18)*('Data Pengujian'!$Q$6:$Q$505="SUCCESS")*('Data Pengujian'!$N$6:$N$505<>""))=0,"",MAX(IF(('Data Pengujian'!$C$6:$C$505=$C$5)*('Data Pengujian'!$F$6:$F$505=$B18)*('Data Pengujian'!$Q$6:$Q$505="SUCCESS")*('Data Pengujian'!$N$6:$N$505<>""),'Data Pengujian'!$N$6:$N$505)))} | L18: =IFERROR(AVERAGEIFS('Data Pengujian'!$I$6:$I$505,'Data Pengujian'!$C$6:$C$505,$C$5,'Data Pengujian'!$F$6:$F$505,$B18,'Data Pengujian'!$Q$6:$Q$505,"SUCCESS"),"") | M18: =IFERROR(AVERAGEIFS('Data Pengujian'!$J$6:$J$505,'Data Pengujian'!$C$6:$C$505,$C$5,'Data Pengujian'!$F$6:$F$505,$B18,'Data Pengujian'!$Q$6:$Q$505,"SUCCESS"),"") | N18: =IFERROR(AVERAGEIFS('Data Pengujian'!$K$6:$K$505,'Data Pengujian'!$C$6:$C$505,$C$5,'Data Pengujian'!$F$6:$F$505,$B18,'Data Pengujian'!$Q$6:$Q$505,"SUCCESS"),"") | O18: =IFERROR(AVERAGEIFS('Data Pengujian'!$L$6:$L$505,'Data Pengujian'!$C$6:$C$505,$C$5,'Data Pengujian'!$F$6:$F$505,$B18,'Data Pengujian'!$Q$6:$Q$505,"SUCCESS"),"") | P18: =IFERROR(AVERAGEIFS('Data Pengujian'!$M$6:$M$505,'Data Pengujian'!$C$6:$C$505,$C$5,'Data Pengujian'!$F$6:$F$505,$B18,'Data Pengujian'!$Q$6:$Q$505,"SUCCESS"),"") | Q18: =IFERROR(AVERAGEIFS('Data Pengujian'!$U$6:$U$505,'Data Pengujian'!$C$6:$C$505,$C$5,'Data Pengujian'!$F$6:$F$505,$B18,'Data Pengujian'!$Q$6:$Q$505,"SUCCESS"),"") | R18: =IFERROR(AVERAGEIFS('Data Pengujian'!$O$6:$O$505,'Data Pengujian'!$C$6:$C$505,$C$5,'Data Pengujian'!$F$6:$F$505,$B18,'Data Pengujian'!$Q$6:$Q$505,"SUCCESS"),"") | S18: =IFERROR(AVERAGEIFS('Data Pengujian'!$W$6:$W$505,'Data Pengujian'!$C$6:$C$505,$C$5,'Data Pengujian'!$F$6:$F$505,$B18,'Data Pengujian'!$Q$6:$Q$505,"SUCCESS"),"") | T18: =IFERROR(SUMPRODUCT(('Data Pengujian'!$C$6:$C$505=$C$5)*('Data Pengujian'!$F$6:$F$505=$B18)*('Data Pengujian'!$Q$6:$Q$505<>"")*'Data Pengujian'!$P$6:$P$505)/SUMPRODUCT(('Data Pengujian'!$C$6:$C$505=$C$5)*('Data Pengujian'!$F$6:$F$505=$B18)*('Data Pengujian'!$Q$6:$Q$505<>"")*('Data Pengujian'!$P$6:$P$505<>"")),"")
B19: 3 | C19: =SUMPRODUCT(('Data Pengujian'!$C$6:$C$505=$C$5)*('Data Pengujian'!$F$6:$F$505=$B19)*('Data Pengujian'!$Q$6:$Q$505<>"")) | D19: =COUNTIFS('Data Pengujian'!$C$6:$C$505,$C$5,'Data Pengujian'!$F$6:$F$505,$B19,'Data Pengujian'!$Q$6:$Q$505,"SUCCESS") | E19: =IF(C19=0,"",1-D19/C19) | F19: =IFERROR(AVERAGEIFS('Data Pengujian'!$N$6:$N$505,'Data Pengujian'!$C$6:$C$505,$C$5,'Data Pengujian'!$F$6:$F$505,$B19,'Data Pengujian'!$Q$6:$Q$505,"SUCCESS"),"") | G19: =IF(SUMPRODUCT(('Data Pengujian'!$C$6:$C$505=$C$5)*('Data Pengujian'!$F$6:$F$505=$B19)*('Data Pengujian'!$Q$6:$Q$505="SUCCESS")*('Data Pengujian'!$N$6:$N$505<>""))<2,"",SQRT(SUMPRODUCT(('Data Pengujian'!$C$6:$C$505=$C$5)*('Data Pengujian'!$F$6:$F$505=$B19)*('Data Pengujian'!$Q$6:$Q$505="SUCCESS")*('Data Pengujian'!$N$6:$N$505<>"")*('Data Pengujian'!$N$6:$N$505-F19)^2)/(SUMPRODUCT(('Data Pengujian'!$C$6:$C$505=$C$5)*('Data Pengujian'!$F$6:$F$505=$B19)*('Data Pengujian'!$Q$6:$Q$505="SUCCESS")*('Data Pengujian'!$N$6:$N$505<>""))-1))) | H19: {=IFERROR(MEDIAN(IF(('Data Pengujian'!$C$6:$C$505=$C$5)*('Data Pengujian'!$F$6:$F$505=$B19)*('Data Pengujian'!$Q$6:$Q$505="SUCCESS")*('Data Pengujian'!$N$6:$N$505<>""),'Data Pengujian'!$N$6:$N$505)),"")} | I19: {=IFERROR(PERCENTILE(IF(('Data Pengujian'!$C$6:$C$505=$C$5)*('Data Pengujian'!$F$6:$F$505=$B19)*('Data Pengujian'!$Q$6:$Q$505="SUCCESS")*('Data Pengujian'!$N$6:$N$505<>""),'Data Pengujian'!$N$6:$N$505),0.95),"")} | J19: {=IF(SUMPRODUCT(('Data Pengujian'!$C$6:$C$505=$C$5)*('Data Pengujian'!$F$6:$F$505=$B19)*('Data Pengujian'!$Q$6:$Q$505="SUCCESS")*('Data Pengujian'!$N$6:$N$505<>""))=0,"",MIN(IF(('Data Pengujian'!$C$6:$C$505=$C$5)*('Data Pengujian'!$F$6:$F$505=$B19)*('Data Pengujian'!$Q$6:$Q$505="SUCCESS")*('Data Pengujian'!$N$6:$N$505<>""),'Data Pengujian'!$N$6:$N$505)))} | K19: {=IF(SUMPRODUCT(('Data Pengujian'!$C$6:$C$505=$C$5)*('Data Pengujian'!$F$6:$F$505=$B19)*('Data Pengujian'!$Q$6:$Q$505="SUCCESS")*('Data Pengujian'!$N$6:$N$505<>""))=0,"",MAX(IF(('Data Pengujian'!$C$6:$C$505=$C$5)*('Data Pengujian'!$F$6:$F$505=$B19)*('Data Pengujian'!$Q$6:$Q$505="SUCCESS")*('Data Pengujian'!$N$6:$N$505<>""),'Data Pengujian'!$N$6:$N$505)))} | L19: =IFERROR(AVERAGEIFS('Data Pengujian'!$I$6:$I$505,'Data Pengujian'!$C$6:$C$505,$C$5,'Data Pengujian'!$F$6:$F$505,$B19,'Data Pengujian'!$Q$6:$Q$505,"SUCCESS"),"") | M19: =IFERROR(AVERAGEIFS('Data Pengujian'!$J$6:$J$505,'Data Pengujian'!$C$6:$C$505,$C$5,'Data Pengujian'!$F$6:$F$505,$B19,'Data Pengujian'!$Q$6:$Q$505,"SUCCESS"),"") | N19: =IFERROR(AVERAGEIFS('Data Pengujian'!$K$6:$K$505,'Data Pengujian'!$C$6:$C$505,$C$5,'Data Pengujian'!$F$6:$F$505,$B19,'Data Pengujian'!$Q$6:$Q$505,"SUCCESS"),"") | O19: =IFERROR(AVERAGEIFS('Data Pengujian'!$L$6:$L$505,'Data Pengujian'!$C$6:$C$505,$C$5,'Data Pengujian'!$F$6:$F$505,$B19,'Data Pengujian'!$Q$6:$Q$505,"SUCCESS"),"") | P19: =IFERROR(AVERAGEIFS('Data Pengujian'!$M$6:$M$505,'Data Pengujian'!$C$6:$C$505,$C$5,'Data Pengujian'!$F$6:$F$505,$B19,'Data Pengujian'!$Q$6:$Q$505,"SUCCESS"),"") | Q19: =IFERROR(AVERAGEIFS('Data Pengujian'!$U$6:$U$505,'Data Pengujian'!$C$6:$C$505,$C$5,'Data Pengujian'!$F$6:$F$505,$B19,'Data Pengujian'!$Q$6:$Q$505,"SUCCESS"),"") | R19: =IFERROR(AVERAGEIFS('Data Pengujian'!$O$6:$O$505,'Data Pengujian'!$C$6:$C$505,$C$5,'Data Pengujian'!$F$6:$F$505,$B19,'Data Pengujian'!$Q$6:$Q$505,"SUCCESS"),"") | S19: =IFERROR(AVERAGEIFS('Data Pengujian'!$W$6:$W$505,'Data Pengujian'!$C$6:$C$505,$C$5,'Data Pengujian'!$F$6:$F$505,$B19,'Data Pengujian'!$Q$6:$Q$505,"SUCCESS"),"") | T19: =IFERROR(SUMPRODUCT(('Data Pengujian'!$C$6:$C$505=$C$5)*('Data Pengujian'!$F$6:$F$505=$B19)*('Data Pengujian'!$Q$6:$Q$505<>"")*'Data Pengujian'!$P$6:$P$505)/SUMPRODUCT(('Data Pengujian'!$C$6:$C$505=$C$5)*('Data Pengujian'!$F$6:$F$505=$B19)*('Data Pengujian'!$Q$6:$Q$505<>"")*('Data Pengujian'!$P$6:$P$505<>"")),"")
B20: 5 | C20: =SUMPRODUCT(('Data Pengujian'!$C$6:$C$505=$C$5)*('Data Pengujian'!$F$6:$F$505=$B20)*('Data Pengujian'!$Q$6:$Q$505<>"")) | D20: =COUNTIFS('Data Pengujian'!$C$6:$C$505,$C$5,'Data Pengujian'!$F$6:$F$505,$B20,'Data Pengujian'!$Q$6:$Q$505,"SUCCESS") | E20: =IF(C20=0,"",1-D20/C20) | F20: =IFERROR(AVERAGEIFS('Data Pengujian'!$N$6:$N$505,'Data Pengujian'!$C$6:$C$505,$C$5,'Data Pengujian'!$F$6:$F$505,$B20,'Data Pengujian'!$Q$6:$Q$505,"SUCCESS"),"") | G20: =IF(SUMPRODUCT(('Data Pengujian'!$C$6:$C$505=$C$5)*('Data Pengujian'!$F$6:$F$505=$B20)*('Data Pengujian'!$Q$6:$Q$505="SUCCESS")*('Data Pengujian'!$N$6:$N$505<>""))<2,"",SQRT(SUMPRODUCT(('Data Pengujian'!$C$6:$C$505=$C$5)*('Data Pengujian'!$F$6:$F$505=$B20)*('Data Pengujian'!$Q$6:$Q$505="SUCCESS")*('Data Pengujian'!$N$6:$N$505<>"")*('Data Pengujian'!$N$6:$N$505-F20)^2)/(SUMPRODUCT(('Data Pengujian'!$C$6:$C$505=$C$5)*('Data Pengujian'!$F$6:$F$505=$B20)*('Data Pengujian'!$Q$6:$Q$505="SUCCESS")*('Data Pengujian'!$N$6:$N$505<>""))-1))) | H20: {=IFERROR(MEDIAN(IF(('Data Pengujian'!$C$6:$C$505=$C$5)*('Data Pengujian'!$F$6:$F$505=$B20)*('Data Pengujian'!$Q$6:$Q$505="SUCCESS")*('Data Pengujian'!$N$6:$N$505<>""),'Data Pengujian'!$N$6:$N$505)),"")} | I20: {=IFERROR(PERCENTILE(IF(('Data Pengujian'!$C$6:$C$505=$C$5)*('Data Pengujian'!$F$6:$F$505=$B20)*('Data Pengujian'!$Q$6:$Q$505="SUCCESS")*('Data Pengujian'!$N$6:$N$505<>""),'Data Pengujian'!$N$6:$N$505),0.95),"")} | J20: {=IF(SUMPRODUCT(('Data Pengujian'!$C$6:$C$505=$C$5)*('Data Pengujian'!$F$6:$F$505=$B20)*('Data Pengujian'!$Q$6:$Q$505="SUCCESS")*('Data Pengujian'!$N$6:$N$505<>""))=0,"",MIN(IF(('Data Pengujian'!$C$6:$C$505=$C$5)*('Data Pengujian'!$F$6:$F$505=$B20)*('Data Pengujian'!$Q$6:$Q$505="SUCCESS")*('Data Pengujian'!$N$6:$N$505<>""),'Data Pengujian'!$N$6:$N$505)))} | K20: {=IF(SUMPRODUCT(('Data Pengujian'!$C$6:$C$505=$C$5)*('Data Pengujian'!$F$6:$F$505=$B20)*('Data Pengujian'!$Q$6:$Q$505="SUCCESS")*('Data Pengujian'!$N$6:$N$505<>""))=0,"",MAX(IF(('Data Pengujian'!$C$6:$C$505=$C$5)*('Data Pengujian'!$F$6:$F$505=$B20)*('Data Pengujian'!$Q$6:$Q$505="SUCCESS")*('Data Pengujian'!$N$6:$N$505<>""),'Data Pengujian'!$N$6:$N$505)))} | L20: =IFERROR(AVERAGEIFS('Data Pengujian'!$I$6:$I$505,'Data Pengujian'!$C$6:$C$505,$C$5,'Data Pengujian'!$F$6:$F$505,$B20,'Data Pengujian'!$Q$6:$Q$505,"SUCCESS"),"") | M20: =IFERROR(AVERAGEIFS('Data Pengujian'!$J$6:$J$505,'Data Pengujian'!$C$6:$C$505,$C$5,'Data Pengujian'!$F$6:$F$505,$B20,'Data Pengujian'!$Q$6:$Q$505,"SUCCESS"),"") | N20: =IFERROR(AVERAGEIFS('Data Pengujian'!$K$6:$K$505,'Data Pengujian'!$C$6:$C$505,$C$5,'Data Pengujian'!$F$6:$F$505,$B20,'Data Pengujian'!$Q$6:$Q$505,"SUCCESS"),"") | O20: =IFERROR(AVERAGEIFS('Data Pengujian'!$L$6:$L$505,'Data Pengujian'!$C$6:$C$505,$C$5,'Data Pengujian'!$F$6:$F$505,$B20,'Data Pengujian'!$Q$6:$Q$505,"SUCCESS"),"") | P20: =IFERROR(AVERAGEIFS('Data Pengujian'!$M$6:$M$505,'Data Pengujian'!$C$6:$C$505,$C$5,'Data Pengujian'!$F$6:$F$505,$B20,'Data Pengujian'!$Q$6:$Q$505,"SUCCESS"),"") | Q20: =IFERROR(AVERAGEIFS('Data Pengujian'!$U$6:$U$505,'Data Pengujian'!$C$6:$C$505,$C$5,'Data Pengujian'!$F$6:$F$505,$B20,'Data Pengujian'!$Q$6:$Q$505,"SUCCESS"),"") | R20: =IFERROR(AVERAGEIFS('Data Pengujian'!$O$6:$O$505,'Data Pengujian'!$C$6:$C$505,$C$5,'Data Pengujian'!$F$6:$F$505,$B20,'Data Pengujian'!$Q$6:$Q$505,"SUCCESS"),"") | S20: =IFERROR(AVERAGEIFS('Data Pengujian'!$W$6:$W$505,'Data Pengujian'!$C$6:$C$505,$C$5,'Data Pengujian'!$F$6:$F$505,$B20,'Data Pengujian'!$Q$6:$Q$505,"SUCCESS"),"") | T20: =IFERROR(SUMPRODUCT(('Data Pengujian'!$C$6:$C$505=$C$5)*('Data Pengujian'!$F$6:$F$505=$B20)*('Data Pengujian'!$Q$6:$Q$505<>"")*'Data Pengujian'!$P$6:$P$505)/SUMPRODUCT(('Data Pengujian'!$C$6:$C$505=$C$5)*('Data Pengujian'!$F$6:$F$505=$B20)*('Data Pengujian'!$Q$6:$Q$505<>"")*('Data Pengujian'!$P$6:$P$505<>"")),"")
B21: 8 | C21: =SUMPRODUCT(('Data Pengujian'!$C$6:$C$505=$C$5)*('Data Pengujian'!$F$6:$F$505=$B21)*('Data Pengujian'!$Q$6:$Q$505<>"")) | D21: =COUNTIFS('Data Pengujian'!$C$6:$C$505,$C$5,'Data Pengujian'!$F$6:$F$505,$B21,'Data Pengujian'!$Q$6:$Q$505,"SUCCESS") | E21: =IF(C21=0,"",1-D21/C21) | F21: =IFERROR(AVERAGEIFS('Data Pengujian'!$N$6:$N$505,'Data Pengujian'!$C$6:$C$505,$C$5,'Data Pengujian'!$F$6:$F$505,$B21,'Data Pengujian'!$Q$6:$Q$505,"SUCCESS"),"") | G21: =IF(SUMPRODUCT(('Data Pengujian'!$C$6:$C$505=$C$5)*('Data Pengujian'!$F$6:$F$505=$B21)*('Data Pengujian'!$Q$6:$Q$505="SUCCESS")*('Data Pengujian'!$N$6:$N$505<>""))<2,"",SQRT(SUMPRODUCT(('Data Pengujian'!$C$6:$C$505=$C$5)*('Data Pengujian'!$F$6:$F$505=$B21)*('Data Pengujian'!$Q$6:$Q$505="SUCCESS")*('Data Pengujian'!$N$6:$N$505<>"")*('Data Pengujian'!$N$6:$N$505-F21)^2)/(SUMPRODUCT(('Data Pengujian'!$C$6:$C$505=$C$5)*('Data Pengujian'!$F$6:$F$505=$B21)*('Data Pengujian'!$Q$6:$Q$505="SUCCESS")*('Data Pengujian'!$N$6:$N$505<>""))-1))) | H21: {=IFERROR(MEDIAN(IF(('Data Pengujian'!$C$6:$C$505=$C$5)*('Data Pengujian'!$F$6:$F$505=$B21)*('Data Pengujian'!$Q$6:$Q$505="SUCCESS")*('Data Pengujian'!$N$6:$N$505<>""),'Data Pengujian'!$N$6:$N$505)),"")} | I21: {=IFERROR(PERCENTILE(IF(('Data Pengujian'!$C$6:$C$505=$C$5)*('Data Pengujian'!$F$6:$F$505=$B21)*('Data Pengujian'!$Q$6:$Q$505="SUCCESS")*('Data Pengujian'!$N$6:$N$505<>""),'Data Pengujian'!$N$6:$N$505),0.95),"")} | J21: {=IF(SUMPRODUCT(('Data Pengujian'!$C$6:$C$505=$C$5)*('Data Pengujian'!$F$6:$F$505=$B21)*('Data Pengujian'!$Q$6:$Q$505="SUCCESS")*('Data Pengujian'!$N$6:$N$505<>""))=0,"",MIN(IF(('Data Pengujian'!$C$6:$C$505=$C$5)*('Data Pengujian'!$F$6:$F$505=$B21)*('Data Pengujian'!$Q$6:$Q$505="SUCCESS")*('Data Pengujian'!$N$6:$N$505<>""),'Data Pengujian'!$N$6:$N$505)))} | K21: {=IF(SUMPRODUCT(('Data Pengujian'!$C$6:$C$505=$C$5)*('Data Pengujian'!$F$6:$F$505=$B21)*('Data Pengujian'!$Q$6:$Q$505="SUCCESS")*('Data Pengujian'!$N$6:$N$505<>""))=0,"",MAX(IF(('Data Pengujian'!$C$6:$C$505=$C$5)*('Data Pengujian'!$F$6:$F$505=$B21)*('Data Pengujian'!$Q$6:$Q$505="SUCCESS")*('Data Pengujian'!$N$6:$N$505<>""),'Data Pengujian'!$N$6:$N$505)))} | L21: =IFERROR(AVERAGEIFS('Data Pengujian'!$I$6:$I$505,'Data Pengujian'!$C$6:$C$505,$C$5,'Data Pengujian'!$F$6:$F$505,$B21,'Data Pengujian'!$Q$6:$Q$505,"SUCCESS"),"") | M21: =IFERROR(AVERAGEIFS('Data Pengujian'!$J$6:$J$505,'Data Pengujian'!$C$6:$C$505,$C$5,'Data Pengujian'!$F$6:$F$505,$B21,'Data Pengujian'!$Q$6:$Q$505,"SUCCESS"),"") | N21: =IFERROR(AVERAGEIFS('Data Pengujian'!$K$6:$K$505,'Data Pengujian'!$C$6:$C$505,$C$5,'Data Pengujian'!$F$6:$F$505,$B21,'Data Pengujian'!$Q$6:$Q$505,"SUCCESS"),"") | O21: =IFERROR(AVERAGEIFS('Data Pengujian'!$L$6:$L$505,'Data Pengujian'!$C$6:$C$505,$C$5,'Data Pengujian'!$F$6:$F$505,$B21,'Data Pengujian'!$Q$6:$Q$505,"SUCCESS"),"") | P21: =IFERROR(AVERAGEIFS('Data Pengujian'!$M$6:$M$505,'Data Pengujian'!$C$6:$C$505,$C$5,'Data Pengujian'!$F$6:$F$505,$B21,'Data Pengujian'!$Q$6:$Q$505,"SUCCESS"),"") | Q21: =IFERROR(AVERAGEIFS('Data Pengujian'!$U$6:$U$505,'Data Pengujian'!$C$6:$C$505,$C$5,'Data Pengujian'!$F$6:$F$505,$B21,'Data Pengujian'!$Q$6:$Q$505,"SUCCESS"),"") | R21: =IFERROR(AVERAGEIFS('Data Pengujian'!$O$6:$O$505,'Data Pengujian'!$C$6:$C$505,$C$5,'Data Pengujian'!$F$6:$F$505,$B21,'Data Pengujian'!$Q$6:$Q$505,"SUCCESS"),"") | S21: =IFERROR(AVERAGEIFS('Data Pengujian'!$W$6:$W$505,'Data Pengujian'!$C$6:$C$505,$C$5,'Data Pengujian'!$F$6:$F$505,$B21,'Data Pengujian'!$Q$6:$Q$505,"SUCCESS"),"") | T21: =IFERROR(SUMPRODUCT(('Data Pengujian'!$C$6:$C$505=$C$5)*('Data Pengujian'!$F$6:$F$505=$B21)*('Data Pengujian'!$Q$6:$Q$505<>"")*'Data Pengujian'!$P$6:$P$505)/SUMPRODUCT(('Data Pengujian'!$C$6:$C$505=$C$5)*('Data Pengujian'!$F$6:$F$505=$B21)*('Data Pengujian'!$Q$6:$Q$505<>"")*('Data Pengujian'!$P$6:$P$505<>"")),"")
B22: Semua | C22: =SUMPRODUCT(('Data Pengujian'!$C$6:$C$505=$C$5)*('Data Pengujian'!$Q$6:$Q$505<>"")) | D22: =COUNTIFS('Data Pengujian'!$C$6:$C$505,$C$5,'Data Pengujian'!$Q$6:$Q$505,"SUCCESS") | E22: =IF(C22=0,"",1-D22/C22) | F22: =IFERROR(AVERAGEIFS('Data Pengujian'!$N$6:$N$505,'Data Pengujian'!$C$6:$C$505,$C$5,'Data Pengujian'!$Q$6:$Q$505,"SUCCESS"),"") | G22: =IF(SUMPRODUCT(('Data Pengujian'!$C$6:$C$505=$C$5)*('Data Pengujian'!$Q$6:$Q$505="SUCCESS")*('Data Pengujian'!$N$6:$N$505<>""))<2,"",SQRT(SUMPRODUCT(('Data Pengujian'!$C$6:$C$505=$C$5)*('Data Pengujian'!$Q$6:$Q$505="SUCCESS")*('Data Pengujian'!$N$6:$N$505<>"")*('Data Pengujian'!$N$6:$N$505-F22)^2)/(SUMPRODUCT(('Data Pengujian'!$C$6:$C$505=$C$5)*('Data Pengujian'!$Q$6:$Q$505="SUCCESS")*('Data Pengujian'!$N$6:$N$505<>""))-1))) | H22: {=IFERROR(MEDIAN(IF(('Data Pengujian'!$C$6:$C$505=$C$5)*('Data Pengujian'!$Q$6:$Q$505="SUCCESS")*('Data Pengujian'!$N$6:$N$505<>""),'Data Pengujian'!$N$6:$N$505)),"")} | I22: {=IFERROR(PERCENTILE(IF(('Data Pengujian'!$C$6:$C$505=$C$5)*('Data Pengujian'!$Q$6:$Q$505="SUCCESS")*('Data Pengujian'!$N$6:$N$505<>""),'Data Pengujian'!$N$6:$N$505),0.95),"")} | J22: {=IF(SUMPRODUCT(('Data Pengujian'!$C$6:$C$505=$C$5)*('Data Pengujian'!$Q$6:$Q$505="SUCCESS")*('Data Pengujian'!$N$6:$N$505<>""))=0,"",MIN(IF(('Data Pengujian'!$C$6:$C$505=$C$5)*('Data Pengujian'!$Q$6:$Q$505="SUCCESS")*('Data Pengujian'!$N$6:$N$505<>""),'Data Pengujian'!$N$6:$N$505)))} | K22: {=IF(SUMPRODUCT(('Data Pengujian'!$C$6:$C$505=$C$5)*('Data Pengujian'!$Q$6:$Q$505="SUCCESS")*('Data Pengujian'!$N$6:$N$505<>""))=0,"",MAX(IF(('Data Pengujian'!$C$6:$C$505=$C$5)*('Data Pengujian'!$Q$6:$Q$505="SUCCESS")*('Data Pengujian'!$N$6:$N$505<>""),'Data Pengujian'!$N$6:$N$505)))} | L22: =IFERROR(AVERAGEIFS('Data Pengujian'!$I$6:$I$505,'Data Pengujian'!$C$6:$C$505,$C$5,'Data Pengujian'!$Q$6:$Q$505,"SUCCESS"),"") | M22: =IFERROR(AVERAGEIFS('Data Pengujian'!$J$6:$J$505,'Data Pengujian'!$C$6:$C$505,$C$5,'Data Pengujian'!$Q$6:$Q$505,"SUCCESS"),"") | N22: =IFERROR(AVERAGEIFS('Data Pengujian'!$K$6:$K$505,'Data Pengujian'!$C$6:$C$505,$C$5,'Data Pengujian'!$Q$6:$Q$505,"SUCCESS"),"") | O22: =IFERROR(AVERAGEIFS('Data Pengujian'!$L$6:$L$505,'Data Pengujian'!$C$6:$C$505,$C$5,'Data Pengujian'!$Q$6:$Q$505,"SUCCESS"),"") | P22: =IFERROR(AVERAGEIFS('Data Pengujian'!$M$6:$M$505,'Data Pengujian'!$C$6:$C$505,$C$5,'Data Pengujian'!$Q$6:$Q$505,"SUCCESS"),"") | Q22: =IFERROR(AVERAGEIFS('Data Pengujian'!$U$6:$U$505,'Data Pengujian'!$C$6:$C$505,$C$5,'Data Pengujian'!$Q$6:$Q$505,"SUCCESS"),"") | R22: =IFERROR(AVERAGEIFS('Data Pengujian'!$O$6:$O$505,'Data Pengujian'!$C$6:$C$505,$C$5,'Data Pengujian'!$Q$6:$Q$505,"SUCCESS"),"") | S22: =IFERROR(AVERAGEIFS('Data Pengujian'!$W$6:$W$505,'Data Pengujian'!$C$6:$C$505,$C$5,'Data Pengujian'!$Q$6:$Q$505,"SUCCESS"),"") | T22: =IFERROR(SUMPRODUCT(('Data Pengujian'!$C$6:$C$505=$C$5)*('Data Pengujian'!$Q$6:$Q$505<>"")*'Data Pengujian'!$P$6:$P$505)/SUMPRODUCT(('Data Pengujian'!$C$6:$C$505=$C$5)*('Data Pengujian'!$Q$6:$Q$505<>"")*('Data Pengujian'!$P$6:$P$505<>"")),"")
B25: ="Perbandingan: "&$C$4&" vs "&$C$5
B26: Durasi Target (mnt) | C26: Rata-rata Total A (dtk) | D26: Rata-rata Total B (dtk) | E26: Selisih B − A (dtk) | F26: Perubahan (%) | G26: Median A (dtk) | H26: Median B (dtk) | I26: Tingkat Gagal A | J26: Tingkat Gagal B | K26: Total Dirasakan User A (dtk) | L26: Total Dirasakan User B (dtk) | M26: Perubahan User (%)
B27: =B9 | C27: =F9 | D27: =F18 | E27: =IF(OR(C27="",D27=""),"",D27-C27) | F27: =IF(OR(C27="",D27="",C27=0),"",(D27-C27)/C27) | G27: =H9 | H27: =H18 | I27: =E9 | J27: =E18 | K27: =R9 | L27: =R18 | M27: =IF(OR(K27="",L27="",K27=0),"",(L27-K27)/K27)
B28: =B10 | C28: =F10 | D28: =F19 | E28: =IF(OR(C28="",D28=""),"",D28-C28) | F28: =IF(OR(C28="",D28="",C28=0),"",(D28-C28)/C28) | G28: =H10 | H28: =H19 | I28: =E10 | J28: =E19 | K28: =R10 | L28: =R19 | M28: =IF(OR(K28="",L28="",K28=0),"",(L28-K28)/K28)
B29: =B11 | C29: =F11 | D29: =F20 | E29: =IF(OR(C29="",D29=""),"",D29-C29) | F29: =IF(OR(C29="",D29="",C29=0),"",(D29-C29)/C29) | G29: =H11 | H29: =H20 | I29: =E11 | J29: =E20 | K29: =R11 | L29: =R20 | M29: =IF(OR(K29="",L29="",K29=0),"",(L29-K29)/K29)
B30: =B12 | C30: =F12 | D30: =F21 | E30: =IF(OR(C30="",D30=""),"",D30-C30) | F30: =IF(OR(C30="",D30="",C30=0),"",(D30-C30)/C30) | G30: =H12 | H30: =H21 | I30: =E12 | J30: =E21 | K30: =R12 | L30: =R21 | M30: =IF(OR(K30="",L30="",K30=0),"",(L30-K30)/K30)
B31: =B13 | C31: =F13 | D31: =F22 | E31: =IF(OR(C31="",D31=""),"",D31-C31) | F31: =IF(OR(C31="",D31="",C31=0),"",(D31-C31)/C31) | G31: =H13 | H31: =H22 | I31: =E13 | J31: =E22 | K31: =R13 | L31: =R22 | M31: =IF(OR(K31="",L31="",K31=0),"",(L31-K31)/K31)
B34: Perubahan negatif = pipeline B lebih cepat dari A.

Sheet Ringkasan Ketahanan
A1: Ringkasan Ketahanan per Fase
A2: Menghitung semua baris yang Status Akhir-nya terisi. Label di kolom B (kuning) bisa diganti.
B4: Tabel 1 — Hasil akhir per label
B5: Label Fase | C5: Mode | D5: n (diuji) | E5: SUCCESS | F5: SILENT_FAILURE | G5: FAILED | H5: TIMEOUT | I5: STUCK | J5: Tingkat Sukses | K5: Tingkat Gagal | L5: Gagal Diam-diam (% dari n) | M5: Gagal Terdeteksi (% dari kegagalan) | N5: Rata-rata Percobaan generate
B6: baseline | C6: =IF(B6="","",IFERROR(INDEX('Data Pengujian'!$D$6:$D$505,MATCH(B6,'Data Pengujian'!$C$6:$C$505,0)),"")) | D6: =IF(B6="","",SUMPRODUCT(('Data Pengujian'!$C$6:$C$505=B6)*('Data Pengujian'!$Q$6:$Q$505<>""))) | E6: =IF(B6="","",COUNTIFS('Data Pengujian'!$C$6:$C$505,B6,'Data Pengujian'!$Q$6:$Q$505,"SUCCESS")) | F6: =IF(B6="","",COUNTIFS('Data Pengujian'!$C$6:$C$505,B6,'Data Pengujian'!$Q$6:$Q$505,"SILENT_FAILURE")) | G6: =IF(B6="","",COUNTIFS('Data Pengujian'!$C$6:$C$505,B6,'Data Pengujian'!$Q$6:$Q$505,"FAILED")) | H6: =IF(B6="","",COUNTIFS('Data Pengujian'!$C$6:$C$505,B6,'Data Pengujian'!$Q$6:$Q$505,"TIMEOUT")) | I6: =IF(B6="","",COUNTIFS('Data Pengujian'!$C$6:$C$505,B6,'Data Pengujian'!$Q$6:$Q$505,"STUCK")) | J6: =IF(OR(B6="",D6=0),"",E6/D6) | K6: =IF(J6="","",1-J6) | L6: =IF(OR(B6="",D6=0),"",F6/D6) | M6: =IF(OR(B6="",D6="",D6-E6=0),"",(G6+H6)/(D6-E6)) | N6: =IF(B6="","",IFERROR(SUMPRODUCT(('Data Pengujian'!$C$6:$C$505=B6)*('Data Pengujian'!$Q$6:$Q$505<>"")*'Data Pengujian'!$P$6:$P$505)/SUMPRODUCT(('Data Pengujian'!$C$6:$C$505=B6)*('Data Pengujian'!$Q$6:$Q$505<>"")*('Data Pengujian'!$P$6:$P$505<>"")),""))
B7: optimized | C7: =IF(B7="","",IFERROR(INDEX('Data Pengujian'!$D$6:$D$505,MATCH(B7,'Data Pengujian'!$C$6:$C$505,0)),"")) | D7: =IF(B7="","",SUMPRODUCT(('Data Pengujian'!$C$6:$C$505=B7)*('Data Pengujian'!$Q$6:$Q$505<>""))) | E7: =IF(B7="","",COUNTIFS('Data Pengujian'!$C$6:$C$505,B7,'Data Pengujian'!$Q$6:$Q$505,"SUCCESS")) | F7: =IF(B7="","",COUNTIFS('Data Pengujian'!$C$6:$C$505,B7,'Data Pengujian'!$Q$6:$Q$505,"SILENT_FAILURE")) | G7: =IF(B7="","",COUNTIFS('Data Pengujian'!$C$6:$C$505,B7,'Data Pengujian'!$Q$6:$Q$505,"FAILED")) | H7: =IF(B7="","",COUNTIFS('Data Pengujian'!$C$6:$C$505,B7,'Data Pengujian'!$Q$6:$Q$505,"TIMEOUT")) | I7: =IF(B7="","",COUNTIFS('Data Pengujian'!$C$6:$C$505,B7,'Data Pengujian'!$Q$6:$Q$505,"STUCK")) | J7: =IF(OR(B7="",D7=0),"",E7/D7) | K7: =IF(J7="","",1-J7) | L7: =IF(OR(B7="",D7=0),"",F7/D7) | M7: =IF(OR(B7="",D7="",D7-E7=0),"",(G7+H7)/(D7-E7)) | N7: =IF(B7="","",IFERROR(SUMPRODUCT(('Data Pengujian'!$C$6:$C$505=B7)*('Data Pengujian'!$Q$6:$Q$505<>"")*'Data Pengujian'!$P$6:$P$505)/SUMPRODUCT(('Data Pengujian'!$C$6:$C$505=B7)*('Data Pengujian'!$Q$6:$Q$505<>"")*('Data Pengujian'!$P$6:$P$505<>"")),""))
B8: baseline-fault30 | C8: =IF(B8="","",IFERROR(INDEX('Data Pengujian'!$D$6:$D$505,MATCH(B8,'Data Pengujian'!$C$6:$C$505,0)),"")) | D8: =IF(B8="","",SUMPRODUCT(('Data Pengujian'!$C$6:$C$505=B8)*('Data Pengujian'!$Q$6:$Q$505<>""))) | E8: =IF(B8="","",COUNTIFS('Data Pengujian'!$C$6:$C$505,B8,'Data Pengujian'!$Q$6:$Q$505,"SUCCESS")) | F8: =IF(B8="","",COUNTIFS('Data Pengujian'!$C$6:$C$505,B8,'Data Pengujian'!$Q$6:$Q$505,"SILENT_FAILURE")) | G8: =IF(B8="","",COUNTIFS('Data Pengujian'!$C$6:$C$505,B8,'Data Pengujian'!$Q$6:$Q$505,"FAILED")) | H8: =IF(B8="","",COUNTIFS('Data Pengujian'!$C$6:$C$505,B8,'Data Pengujian'!$Q$6:$Q$505,"TIMEOUT")) | I8: =IF(B8="","",COUNTIFS('Data Pengujian'!$C$6:$C$505,B8,'Data Pengujian'!$Q$6:$Q$505,"STUCK")) | J8: =IF(OR(B8="",D8=0),"",E8/D8) | K8: =IF(J8="","",1-J8) | L8: =IF(OR(B8="",D8=0),"",F8/D8) | M8: =IF(OR(B8="",D8="",D8-E8=0),"",(G8+H8)/(D8-E8)) | N8: =IF(B8="","",IFERROR(SUMPRODUCT(('Data Pengujian'!$C$6:$C$505=B8)*('Data Pengujian'!$Q$6:$Q$505<>"")*'Data Pengujian'!$P$6:$P$505)/SUMPRODUCT(('Data Pengujian'!$C$6:$C$505=B8)*('Data Pengujian'!$Q$6:$Q$505<>"")*('Data Pengujian'!$P$6:$P$505<>"")),""))
B9: optimized-fault30 | C9: =IF(B9="","",IFERROR(INDEX('Data Pengujian'!$D$6:$D$505,MATCH(B9,'Data Pengujian'!$C$6:$C$505,0)),"")) | D9: =IF(B9="","",SUMPRODUCT(('Data Pengujian'!$C$6:$C$505=B9)*('Data Pengujian'!$Q$6:$Q$505<>""))) | E9: =IF(B9="","",COUNTIFS('Data Pengujian'!$C$6:$C$505,B9,'Data Pengujian'!$Q$6:$Q$505,"SUCCESS")) | F9: =IF(B9="","",COUNTIFS('Data Pengujian'!$C$6:$C$505,B9,'Data Pengujian'!$Q$6:$Q$505,"SILENT_FAILURE")) | G9: =IF(B9="","",COUNTIFS('Data Pengujian'!$C$6:$C$505,B9,'Data Pengujian'!$Q$6:$Q$505,"FAILED")) | H9: =IF(B9="","",COUNTIFS('Data Pengujian'!$C$6:$C$505,B9,'Data Pengujian'!$Q$6:$Q$505,"TIMEOUT")) | I9: =IF(B9="","",COUNTIFS('Data Pengujian'!$C$6:$C$505,B9,'Data Pengujian'!$Q$6:$Q$505,"STUCK")) | J9: =IF(OR(B9="",D9=0),"",E9/D9) | K9: =IF(J9="","",1-J9) | L9: =IF(OR(B9="",D9=0),"",F9/D9) | M9: =IF(OR(B9="",D9="",D9-E9=0),"",(G9+H9)/(D9-E9)) | N9: =IF(B9="","",IFERROR(SUMPRODUCT(('Data Pengujian'!$C$6:$C$505=B9)*('Data Pengujian'!$Q$6:$Q$505<>"")*'Data Pengujian'!$P$6:$P$505)/SUMPRODUCT(('Data Pengujian'!$C$6:$C$505=B9)*('Data Pengujian'!$Q$6:$Q$505<>"")*('Data Pengujian'!$P$6:$P$505<>"")),""))
B10: baseline-hang20 | C10: =IF(B10="","",IFERROR(INDEX('Data Pengujian'!$D$6:$D$505,MATCH(B10,'Data Pengujian'!$C$6:$C$505,0)),"")) | D10: =IF(B10="","",SUMPRODUCT(('Data Pengujian'!$C$6:$C$505=B10)*('Data Pengujian'!$Q$6:$Q$505<>""))) | E10: =IF(B10="","",COUNTIFS('Data Pengujian'!$C$6:$C$505,B10,'Data Pengujian'!$Q$6:$Q$505,"SUCCESS")) | F10: =IF(B10="","",COUNTIFS('Data Pengujian'!$C$6:$C$505,B10,'Data Pengujian'!$Q$6:$Q$505,"SILENT_FAILURE")) | G10: =IF(B10="","",COUNTIFS('Data Pengujian'!$C$6:$C$505,B10,'Data Pengujian'!$Q$6:$Q$505,"FAILED")) | H10: =IF(B10="","",COUNTIFS('Data Pengujian'!$C$6:$C$505,B10,'Data Pengujian'!$Q$6:$Q$505,"TIMEOUT")) | I10: =IF(B10="","",COUNTIFS('Data Pengujian'!$C$6:$C$505,B10,'Data Pengujian'!$Q$6:$Q$505,"STUCK")) | J10: =IF(OR(B10="",D10=0),"",E10/D10) | K10: =IF(J10="","",1-J10) | L10: =IF(OR(B10="",D10=0),"",F10/D10) | M10: =IF(OR(B10="",D10="",D10-E10=0),"",(G10+H10)/(D10-E10)) | N10: =IF(B10="","",IFERROR(SUMPRODUCT(('Data Pengujian'!$C$6:$C$505=B10)*('Data Pengujian'!$Q$6:$Q$505<>"")*'Data Pengujian'!$P$6:$P$505)/SUMPRODUCT(('Data Pengujian'!$C$6:$C$505=B10)*('Data Pengujian'!$Q$6:$Q$505<>"")*('Data Pengujian'!$P$6:$P$505<>"")),""))
B11: optimized-hang20 | C11: =IF(B11="","",IFERROR(INDEX('Data Pengujian'!$D$6:$D$505,MATCH(B11,'Data Pengujian'!$C$6:$C$505,0)),"")) | D11: =IF(B11="","",SUMPRODUCT(('Data Pengujian'!$C$6:$C$505=B11)*('Data Pengujian'!$Q$6:$Q$505<>""))) | E11: =IF(B11="","",COUNTIFS('Data Pengujian'!$C$6:$C$505,B11,'Data Pengujian'!$Q$6:$Q$505,"SUCCESS")) | F11: =IF(B11="","",COUNTIFS('Data Pengujian'!$C$6:$C$505,B11,'Data Pengujian'!$Q$6:$Q$505,"SILENT_FAILURE")) | G11: =IF(B11="","",COUNTIFS('Data Pengujian'!$C$6:$C$505,B11,'Data Pengujian'!$Q$6:$Q$505,"FAILED")) | H11: =IF(B11="","",COUNTIFS('Data Pengujian'!$C$6:$C$505,B11,'Data Pengujian'!$Q$6:$Q$505,"TIMEOUT")) | I11: =IF(B11="","",COUNTIFS('Data Pengujian'!$C$6:$C$505,B11,'Data Pengujian'!$Q$6:$Q$505,"STUCK")) | J11: =IF(OR(B11="",D11=0),"",E11/D11) | K11: =IF(J11="","",1-J11) | L11: =IF(OR(B11="",D11=0),"",F11/D11) | M11: =IF(OR(B11="",D11="",D11-E11=0),"",(G11+H11)/(D11-E11)) | N11: =IF(B11="","",IFERROR(SUMPRODUCT(('Data Pengujian'!$C$6:$C$505=B11)*('Data Pengujian'!$Q$6:$Q$505<>"")*'Data Pengujian'!$P$6:$P$505)/SUMPRODUCT(('Data Pengujian'!$C$6:$C$505=B11)*('Data Pengujian'!$Q$6:$Q$505<>"")*('Data Pengujian'!$P$6:$P$505<>"")),""))
B12: Gagal Terdeteksi = (FAILED + TIMEOUT) / semua kegagalan. Nilai tinggi berarti user diberi tahu saat gagal, bukan menerima skor 0 diam-diam.
B14: Tabel 2 — Tingkat gagal per durasi video
B15: Label Fase | C15: 1 | D15: 3 | E15: 5 | F15: 8
B16: =IF(B6="","",B6) | C16: =IF($B16="","",IF(SUMPRODUCT(('Data Pengujian'!$C$6:$C$505=$B16)*('Data Pengujian'!$F$6:$F$505=C$15)*('Data Pengujian'!$Q$6:$Q$505<>""))=0,"",1-COUNTIFS('Data Pengujian'!$C$6:$C$505,$B16,'Data Pengujian'!$F$6:$F$505,C$15,'Data Pengujian'!$Q$6:$Q$505,"SUCCESS")/SUMPRODUCT(('Data Pengujian'!$C$6:$C$505=$B16)*('Data Pengujian'!$F$6:$F$505=C$15)*('Data Pengujian'!$Q$6:$Q$505<>"")))) | D16: =IF($B16="","",IF(SUMPRODUCT(('Data Pengujian'!$C$6:$C$505=$B16)*('Data Pengujian'!$F$6:$F$505=D$15)*('Data Pengujian'!$Q$6:$Q$505<>""))=0,"",1-COUNTIFS('Data Pengujian'!$C$6:$C$505,$B16,'Data Pengujian'!$F$6:$F$505,D$15,'Data Pengujian'!$Q$6:$Q$505,"SUCCESS")/SUMPRODUCT(('Data Pengujian'!$C$6:$C$505=$B16)*('Data Pengujian'!$F$6:$F$505=D$15)*('Data Pengujian'!$Q$6:$Q$505<>"")))) | E16: =IF($B16="","",IF(SUMPRODUCT(('Data Pengujian'!$C$6:$C$505=$B16)*('Data Pengujian'!$F$6:$F$505=E$15)*('Data Pengujian'!$Q$6:$Q$505<>""))=0,"",1-COUNTIFS('Data Pengujian'!$C$6:$C$505,$B16,'Data Pengujian'!$F$6:$F$505,E$15,'Data Pengujian'!$Q$6:$Q$505,"SUCCESS")/SUMPRODUCT(('Data Pengujian'!$C$6:$C$505=$B16)*('Data Pengujian'!$F$6:$F$505=E$15)*('Data Pengujian'!$Q$6:$Q$505<>"")))) | F16: =IF($B16="","",IF(SUMPRODUCT(('Data Pengujian'!$C$6:$C$505=$B16)*('Data Pengujian'!$F$6:$F$505=F$15)*('Data Pengujian'!$Q$6:$Q$505<>""))=0,"",1-COUNTIFS('Data Pengujian'!$C$6:$C$505,$B16,'Data Pengujian'!$F$6:$F$505,F$15,'Data Pengujian'!$Q$6:$Q$505,"SUCCESS")/SUMPRODUCT(('Data Pengujian'!$C$6:$C$505=$B16)*('Data Pengujian'!$F$6:$F$505=F$15)*('Data Pengujian'!$Q$6:$Q$505<>""))))
